Workbook
Name Alignment: 'Document Control'!$G$7
Name BusinessProcessFlowLinks: 'Document Control'!$C$12
Name BusinessValue: 'Document Control'!$C$18
Name ChangeSummary: 'Document Control'!$C$19
Name CustomerAssumptions: 'Document Control'!$C$16
Name CustomerDescription: 'Document Control'!$C$17
Name CustomerPoints: 'Document Control'!$G$12
Name Description: 'Document Control'!$C$14
Name FastPathFactor: 'Document Control'!$C$11
Name GWID: 'Document Control'!$G$6
Name isFastPath: 'Document Control'!$C$10
Name Product: 'Document Control'!$C$4
Name RiskRating: 'Document Control'!$G$8
Name StoryAssumptions: 'Document Control'!$C$15
Name StoryName: 'Document Control'!$C$5
Name StoryNumber: 'Document Control'!$G$4
Name StoryPoints: 'Document Control'!$G$11
Name StoryType: 'Document Control'!$C$8
Name Theme: 'Document Control'!$C$6
Name ValueScore: 'Document Control'!$C$7
Name WorkBucketType: 'Document Control'!$G$10

Sheet Document Control
B1: User Story Card - Document Control
B2: Track general user story information and change control details
B4: Product | C4: PC | E4: Story Card # | G4: US444
B5: Story Card Name | C5: Policy Info | E5: Status | G5: Not Started
B6: Theme | C6: QuoteApplication | E6: GW-ID | G6: 10900-GW.2
B7: Gap Business Value | C7: 3 - Significant Value | E7: Product Alignment | G7: 4 - Full Product Alignment
B8: Story Type | C8: Project | E8: Risk Rating | G8: 1. Critical
B9: User Story Owner | E9: SMEs
E10: Work Bucket Type | G10: FUN_Standard
E11: Base Estimate (Points) | G11: 8
B12: Business Process Flow Links | E12: Customer Estimate (Points) | G12: 0
B14: Standard Description | C14: As a PolicyCenter user with the role of Agent, CSR, Underwriter, or Manager I want to be able to enter and maintain policy information including name insured, additional named insured, policy term and underwriting company information.
B15: Base Estimate Assumptions | C15: The policy info screen is assumed to be common across all LOB's so has been removed from the LOB specific stories and put into common. If you have LOB specific requirements, these could be added as new gap stories but best practice is to define a single policy info screen. The estimate includes validation rules for effective / written dates - backdating and forward dating. Any complex producer code and UW assignment is out of scope. Logic that varies across multiple LOB's is out of scope. The estimate assumes minimal UI changes on the policy info screen and additional / named insured screens including simple UI logic and validation rules. Estimate includes2 to 3 new UI fields 1 of which is a typelist. Complex workflow changes should be defined in a separate gap story. Does not include prefill functionality. The base estimate does not make provision for UW Rules (Issues/Validations). UW Rule work is handled in the UW Rule Theme Stories.
B16: Customer Estimate Assumptions
B17: Customer Description
B18: Business Value of Modifications to Base Product
B19: Change Summary
B21: Pre-Conditions | C21: None
B22: Known Gaps | C22: None
B25: Document Control - Amendment History
B26: Version Number | C26: Description of Change | G26: Person Making Change | I26: Date | J26: Wave or Release | K26: LOB
B27: 1 | C27: Base Configuration | G27: N/A

Sheet UI Mockup
B1: User Story Card - UI Mockup
B2: Create screen shots of the proposed user interface (UI) for this story
B4: Product | C4: ='Document Control'!C4 -> PC | E4: Story Card # | G4: ='Document Control'!G4 -> US444
B5: Story Card Name | C5: ='Document Control'!C5 -> Policy Info | E5: Status | G5: ='Document Control'!G5 -> Not Started
B6: Theme | C6: ='Document Control'!C6 -> QuoteApplication | E6: GW-ID | G6: ='Document Control'!G6 -> 10900-GW.2
B7: ='Document Control'!B7 -> Gap Business Value | C7: ='Document Control'!C7 -> 3 - Significant Value | E7: Product Alignment | G7: ='Document Control'!G7 -> 4 - Full Product Alignment
B8: Story Type | C8: ='Document Control'!C8 -> Project | E8: Risk Rating | G8: ='Document Control'!G8 -> 1. Critical
B9: User Story Owner | C9: ='Document Control'!C9 -> 0 | E9: SMEs | G9: ='Document Control'!G9 -> 0
C10: ='Document Control'!C10 | E10: Work Bucket Type | G10: ='Document Control'!G10 -> FUN_Standard
C11: ='Document Control'!C11 | E11: Base Estimate (Points) | G11: ='Document Control'!G11 -> 8
B12: Business Process Flow Links | C12: ='Document Control'!C12 -> 0 | E12: Customer Estimate (Points) | G12: ='Document Control'!G12 -> 0
B13: All Screen annotations must include the appropriate Requirement Number
B14: 01 Policy Info Landing Page 1 : SubmissionWizard.pcf
B45: 01 Policy Info Landing Page 2 : SubmissionWizard.pcf
B76: 02 Policy Info Details 1 : SubmissionWizard.pcf
B107: 02 Policy Info Details 2 : SubmissionWizard.pcf

Sheet UI Fields
B1: User Story Card - UI Fields
B2: Track the UI fields and related details for the screens included in the user story
B4: Product | D4: ='Document Control'!C4 -> PC | F4: Story Card # | H4: ='Document Control'!G4 -> US444
B5: Story Card Name | D5: ='Document Control'!C5 -> Policy Info | F5: Status | H5: ='Document Control'!G5 -> Not Started
B6: Theme | D6: ='Document Control'!C6 -> QuoteApplication | F6: GW-ID | H6: ='Document Control'!G6 -> 10900-GW.2
B7: ='Document Control'!B7 -> Gap Business Value | D7: ='Document Control'!C7 -> 3 - Significant Value | F7: Product Alignment | H7: ='Document Control'!G7 -> 4 - Full Product Alignment
B8: Story Type | D8: ='Document Control'!C8 -> Project | F8: Risk Rating | H8: ='Document Control'!G8 -> 1. Critical
B9: User Story Owner | D9: ='Document Control'!C9 -> 0 | F9: SMEs | H9: ='Document Control'!G9 -> 0
D10: ='Document Control'!C10 | F10: Work Bucket Type | H10: ='Document Control'!G10 -> FUN_Standard
D11: ='Document Control'!C11 | F11: Base Estimate (Points) | H11: ='Document Control'!G11 -> 8
B12: Business Process Flow Links | D12: ='Document Control'!C12 -> 0 | F12: Customer Estimate (Points) | H12: ='Document Control'!G12 -> 0
B14: Functional Details
B15: Requirement Number | C15: Name of DV or LV | D15: Base Product, New, Modified | E15: Display Key | F15: Label | G15: Label (Locatlized) | H15: Path | I15: Table | J15: Field Name | K15: Field Type | L15: Field Length | M15: Typelist | N15: Editable | O15: Mandatory Field | P15: Visible | Q15: Available | R15: Default Value | S15: Permissions | T15: Notes, Conditions, Dependencies (Reset, Display, Validation, Error) | U15: Label (Locatlized)2 | V15: Wave or Release | W15: LOB
B16: SubmissionWizard.pcf
C17: SubmissionWizard_PolicyInfoDV
C18: SubmissionWizard_PolicyInfoDV | D18: OOTB | E18: Web.SubmissionWizard.DateQuoteNeeded | F18: Date Quote Needed | H18: submission.DateQuoteNeeded | I18: pc_job | J18: DateQuoteNeeded | K18: datetime | N18: TRUE | O18: FALSE | P18: TRUE | W18: Personal Auto
C19: SubmissionWizard_PolicyInfoDV | D19: OOTB | E19: Web.PolicyPeriod.EstimatedPremium | F19: Estimated Premium | H19: policyPeriod.EstimatedPremium | I19: pc_policyperiod | J19: EstimatedPremium | K19: MonetaryAmount | N19: TRUE | O19: FALSE | P19: policyPeriod.Policy.Product.ProductType == TC_COMMERCIAL | W19: Personal Auto
C20: SubmissionWizard_PolicyInfoDV | D20: OOTB | H20: policyPeriod.UWCompany | I20: pc_policyperiod | J20: UWCompany | K20: Foreign Key | N20: perm.System.multicompquote | O20: FALSE | W20: Personal Auto
C21: SubmissionWizard_PolicyInfoDV | D21: OOTB | H21: displaykey.Web.Policy.UWCompanies.AutoSelect | N21: FALSE | O21: FALSE | P21: not perm.System.multicompquote | W21: Personal Auto
C22: AccountInfoInputSet
C23: AccountInfoInputSet | D23: OOTB | E23: Web.Policy.Account.PrimaryInsured | F23: Primary Named Insured | N23: FALSE | O23: FALSE | P23: not openForEdit | W23: Personal Auto
C24: AccountInfoInputSet | D24: OOTB | E24: Web.Policy.Account.PrimaryInsured | F24: Primary Named Insured | H24: displaykey.Web.Policy.Account.PrimaryInsured.ChangeTo | N24: FALSE | O24: FALSE | P24: openForEdit | W24: Personal Auto
C25: AccountInfoInputSet | D25: OOTB | E25: Web.Policy.Account.Applicant.Name | F25: Name | H25: primaryNamedInsured.DisplayName | N25: FALSE | O25: FALSE | W25: Personal Auto
C26: AccountInfoInputSet | D26: OOTB | E26: Web.Policy.Address | F26: Policy Address | H26: displaykey.Web.Policy.Account.PrimaryInsured.ChangeTo | N26: FALSE | O26: FALSE | P26: openForEdit | W26: Personal Auto
C27: AccountInfoInputSet | D27: OOTB | E27: Web.SubmissionWizard.NamedInsured.IndustryCode | F27: Industry Code | H27: primaryNamedInsured.IndustryCode | N27: TRUE | O27: primaryNamedInsured.Branch.HasWorkersComp | P27: primaryNamedInsured.Branch.Policy.Product.isContactTypeSuitableForProductAccountType(Company) | W27: Personal Auto
C28: AccountInfoInputSet | D28: OOTB | E28: Web.Policy.Account.WC.AssignedRisk | F28: Assigned Risk? | H28: period.AssignedRisk | I28: pc_policyperiod | J28: AssignedRisk | K28: bit | N28: TRUE | O28: FALSE | P28: period.HasWorkersComp | W28: Personal Auto
C29: AccountInfoInputSet | D29: OOTB | E29: Web.Policy.Account.WC.YearBusinessStarted | F29: Year Business Started | H29: period.Policy.Account.YearBusinessStarted | I29: pc_account | J29: YearBusinessStarted | K29: year | N29: period.Policy.Account.Editable | O29: FALSE | P29: period.Policy.Product.Commercial | W29: Personal Auto
C30: AccountInfoInputSet | D30: OOTB | E30: Web.Policy.Account.WC.BusOps | F30: Description of business and operations | H30: period.Policy.Account.BusOpsDesc | I30: pc_account | J30: BusOpsDesc | K30: varchar | L30: 240 | N30: period.Policy.Account.Editable | O30: FALSE | P30: period.Policy.Product.Commercial | W30: Personal Auto
C31: AccountInfoInputSet | D31: OOTB | E31: Web.Policy.Account.OrganizationType | F31: Organization Type | H31: period.Policy.Account.AccountOrgType | I31: pc_account | J31: AccountOrgType | K31: Type Key | M31: AccountOrgType | N31: period.Policy.Account.Editable | O31: TRUE | P31: period.Policy.Product.isContactTypeSuitableForProductAccountType(Company) | W31: Personal Auto
C32: AccountInfoInputSet | D32: OOTB | E32: Web.Policy.Account.OrganizationTypeOtherDescription | F32: Description | H32: period.Policy.Account.OtherOrgTypeDescription | I32: pc_account | J32: OtherOrgTypeDescription | K32: varchar | L32: 40 | N32: period.Policy.Account.Editable | O32: TRUE | P32: period.Policy.Account.AccountOrgType == TC_OTHER | W32: Personal Auto
C33: GlobalPhoneInputSet
C34: GlobalPhoneInputSet | D34: OOTB | E34: DisplayKey.get(""Web.ContactDetail.Phone.MultiField.RegionCode"", phoneOwner.WidgetLabel) | F34: null: Region Code | H34: phoneOwner.PhoneFields.CountryCode | N34: phoneOwner.isEditable(gw.api.phone.PhoneOwnerFieldId.COUNTRY_CODE) | O34: phoneOwner.isRegionCodeRequired() || phoneOwner.PhoneFields.NationalSubscriberNumber != null | P34: isVisible(phoneOwner, gw.api.phone.PhoneOwnerFieldId.COUNTRY_CODE) | W34: Personal Auto
C35: GlobalPhoneInputSet | D35: OOTB | E35: phoneOwner.getPhoneLabel(singleInput) | F35: <unknown> | H35: phoneOwner.PhoneFields.NationalSubscriberNumber | N35: phoneOwner.isEditable(gw.api.phone.PhoneOwnerFieldId.NATIONAL_SUBSCRIBER_NUMBER) | O35: phoneOwner.isRequired(gw.api.phone.PhoneOwnerFieldId.NATIONAL_SUBSCRIBER_NUMBER) | P35: isVisible(phoneOwner, gw.api.phone.PhoneOwnerFieldId.NATIONAL_SUBSCRIBER_NUMBER) | W35: Personal Auto
C36: GlobalPhoneInputSet | D36: OOTB | E36: DisplayKey.get(""Web.ContactDetail.Phone.MultiField.Extension"", phoneOwner.WidgetLabel) | F36: null: Extension | H36: phoneOwner.PhoneFields.Extension | N36: TRUE | O36: TRUE | P36: isVisible(phoneOwner, gw.api.phone.PhoneOwnerFieldId.EXTENSION) | W36: Personal Auto
C37: GlobalPhoneInputSet | D37: OOTB | E37: phoneOwner.WidgetLabel | H37: phoneOwner.format() | N37: FALSE | O37: FALSE | P37: isVisible(phoneOwner, gw.api.phone.PhoneOwnerFieldId.PHONE_DISPLAY) | W37: Personal Auto
C38: PolicyAddressDisplayInputSet
C39: PolicyAddressDisplayInputSet | D39: OOTB | E39: Web.ContactDetail.AddressDetail.AddressType | F39: Address Type | H39: period.PolicyAddress.AddressType | N39: FALSE | O39: FALSE | W39: Personal Auto
C40: PolicyAddressDisplayInputSet | D40: OOTB | E40: Web.ContactDetail.AddressDetail.Description | F40: Address Description | H40: period.PolicyAddress.Description | N40: FALSE | O40: FALSE | W40: Personal Auto
C41: GlobalAddressInputSet.default
C42: GlobalAddressInputSet.default | D42: OOTB | E42: addressOwner.AddressNameLabel | H42: new gw.api.address.AddressFormatter().format(addressOwner.AddressDelegate, ""\n"") | N42: FALSE | O42: FALSE | P42: addressOwner.ShowAddressSummary | W42: Personal Auto
...

Sheet Typelists
B1: User Story Card - Typelists
B2: Track any new typelists and the associated typecodes included in the user story
B4: Product | D4: ='Document Control'!C4 -> PC | F4: Story Card # | H4: ='Document Control'!G4 -> US444
B5: Story Card Name | D5: ='Document Control'!C5 -> Policy Info | F5: Status | H5: ='Document Control'!G5 -> Not Started
B6: Theme | D6: ='Document Control'!C6 -> QuoteApplication | F6: GW-ID | H6: ='Document Control'!G6 -> 10900-GW.2
B7: ='Document Control'!B7 -> Gap Business Value | D7: ='Document Control'!C7 -> 3 - Significant Value | F7: Product Alignment | H7: ='Document Control'!G7 -> 4 - Full Product Alignment
B8: Story Type | D8: ='Document Control'!C8 -> Project | F8: Risk Rating | H8: ='Document Control'!G8 -> 1. Critical
B9: User Story Owner | D9: ='Document Control'!C9 -> 0 | F9: SMEs | H9: ='Document Control'!G9 -> 0
D10: ='Document Control'!C10 | F10: Work Bucket Type | H10: ='Document Control'!G10 -> FUN_Standard
D11: ='Document Control'!C11 | F11: Base Estimate (Points) | H11: ='Document Control'!G11 -> 8
B12: Business Process Flow Links | D12: ='Document Control'!C12 -> 0 | F12: Customer Estimate (Points) | H12: ='Document Control'!G12 -> 0
B14: Functional Details
B15: Name of Typelist | C15: New, Modified | D15: Code | E15: Typecode Name | F15: Typecode Name (Locale) | G15: Typecode Description | H15: Typecode Description (Locale) | I15: Priority | J15: Retired | K15: Conditions | L15: Column1 | M15: Wave or Release | N15: LOB | O15: Requirement Number
B16: AccountOrgType
B17: AccountOrgType | C17: OOTB | D17: individual | E17: individual | G17: individual | I17: 0 | J17: FALSE
B18: AccountOrgType | C18: OOTB | D18: solepropship | E18: solepropship | G18: solepropship | I18: 0 | J18: FALSE
B19: AccountOrgType | C19: OOTB | D19: partnership | E19: partnership | G19: partnership | I19: 0 | J19: FALSE
B20: AccountOrgType | C20: OOTB | D20: corporation | E20: corporation | G20: corporation | I20: 0 | J20: FALSE
B21: AccountOrgType | C21: OOTB | D21: privatecorp | E21: privatecorp | G21: privatecorp | I21: 0 | J21: FALSE
B22: AccountOrgType | C22: OOTB | D22: llc | E22: llc | G22: llc | I22: 0 | J22: FALSE
B23: AccountOrgType | C23: OOTB | D23: jointventure | E23: jointventure | G23: jointventure | I23: 0 | J23: FALSE
B24: AccountOrgType | C24: OOTB | D24: commonownership | E24: commonownership | G24: commonownership | I24: 0 | J24: FALSE
B25: AccountOrgType | C25: OOTB | D25: limitedpartnership | E25: limitedpartnership | G25: limitedpartnership | I25: 0 | J25: FALSE
B26: AccountOrgType | C26: OOTB | D26: trustestate | E26: trustestate | G26: trustestate | I26: 0 | J26: FALSE
B27: AccountOrgType | C27: OOTB | D27: executortrustee | E27: executortrustee | G27: executortrustee | I27: 0 | J27: FALSE
B28: AccountOrgType | C28: OOTB | D28: llp | E28: llp | G28: llp | I28: 0 | J28: FALSE
... B32: AccountOrgType | C32: OOTB | D32: other | E32: other | G32: other | I32: 0 | J32: FALSE
B33: Jurisdiction
B34: Jurisdiction | C34: OOTB | D34: AK | E34: AK | G34: AK | I34: 0 | J34: FALSE
B35: Jurisdiction | C35: OOTB | D35: AL | E35: AL | G35: AL | I35: 0 | J35: FALSE
B36: Jurisdiction | C36: OOTB | D36: AR | E36: AR | G36: AR | I36: 0 | J36: FALSE
B37: Jurisdiction | C37: OOTB | D37: AZ | E37: AZ | G37: AZ | I37: 0 | J37: FALSE
B38: Jurisdiction | C38: OOTB | D38: CA | E38: CA | G38: CA | I38: 0 | J38: FALSE
B39: Jurisdiction | C39: OOTB | D39: CO | E39: CO | G39: CO | I39: 0 | J39: FALSE
B40: Jurisdiction | C40: OOTB | D40: CT | E40: CT | G40: CT | I40: 0 | J40: FALSE
B41: Jurisdiction | C41: OOTB | D41: DC | E41: DC | G41: DC | I41: 0 | J41: FALSE
B42: Jurisdiction | C42: OOTB | D42: DE | E42: DE | G42: DE | I42: 0 | J42: FALSE
B43: Jurisdiction | C43: OOTB | D43: FL | E43: FL | G43: FL | I43: 0 | J43: FALSE
B44: Jurisdiction | C44: OOTB | D44: GA | E44: GA | G44: GA | I44: 0 | J44: FALSE
B45: Jurisdiction | C45: OOTB | D45: HI | E45: HI | G45: HI | I45: 0 | J45: FALSE
...

Sheet UI Validation & Business Rules
B1: User Story Card - UI Validation & Business Rules
B2: Track any validation and/or business rules related to this story or link to a Master Business Rules Spreadsheet
B4: Product | C4: ='Document Control'!C4 -> PC | D4: Story Card # | E4: ='Document Control'!G4 -> US444
B5: Story Card Name | C5: ='Document Control'!C5 -> Policy Info | D5: Status | E5: ='Document Control'!G5 -> Not Started
B6: Theme | C6: ='Document Control'!C6 -> QuoteApplication | D6: GW-ID | E6: ='Document Control'!G6 -> 10900-GW.2
B7: ='Document Control'!B7 -> Gap Business Value | C7: ='Document Control'!C7 -> 3 - Significant Value | D7: Product Alignment | E7: ='Document Control'!G7 -> 4 - Full Product Alignment
B8: Story Type | C8: ='Document Control'!C8 -> Project | D8: Risk Rating | E8: ='Document Control'!G8 -> 1. Critical
B9: User Story Owner | C9: ='Document Control'!C9 -> 0 | D9: SMEs | E9: ='Document Control'!G9 -> 0
C10: ='Document Control'!C10 | D10: Work Bucket Type | E10: ='Document Control'!G10 -> FUN_Standard
C11: ='Document Control'!C11 | D11: Base Estimate (Points) | E11: ='Document Control'!G11 -> 8
B12: Business Process Flow Links | C12: ='Document Control'!C12 -> 0 | D12: Customer Estimate (Points) | E12: ='Document Control'!G12 -> 0
B14: Validation Details
B15: Name of DV or LV | C15: Field or Filter | D15: Rules or Conditions | E15: Error or Warning? | F15: Warning or Error Message | G15: Comments | H15: Wave or Release | I15: LOB | J15: Reference ID
B16: SubmissionWizard_PolicyInfoScreen.pcf | C16: Underwriting Companies | D16: PolicyPeriod.getUWCompaniesForStates(true).toTypedArray() is called to determine list of valid values | E16: Error | G16: There is logic in the PCF to validate UWCompany - An error message is shown if it is not valid | J16: PC10.VAL.1
B17: SubmissionWizard_PolicyInfoScreen.pcf | C17: TermType | D17: Changing the termtype Updates the Expiration Date of the policy | J17: PC10.VAL.2
B18: SubmissionWizard_PolicyInfoScreen.pcf | C18: Effective Date | D18: Changing the effective date updates the expiration date | J18: PC10.VAL.3
B19: SubmissionWizard_PolicyInfoScreen.pcf | C19: Expiration Date | D19: Changing the expiration date updates the term type | G19: Expiration Date is editable only for policy term "Other" | J19: PC10.VAL.4

Sheet Action Items
B1: User Story Card - Action Items
B2: Track relevant action items for the user story; most commonly used during Inception workshops
B4: Product | C4: ='Document Control'!C4 -> PC | E4: Story Card # | G4: ='Document Control'!G4 -> US444
B5: Story Card Name | C5: ='Document Control'!C5 -> Policy Info | E5: Status | G5: ='Document Control'!G5 -> Not Started
B6: Theme | C6: ='Document Control'!C6 -> QuoteApplication | E6: GW-ID | G6: ='Document Control'!G6 -> 10900-GW.2
B7: ='Document Control'!B7 -> Gap Business Value | C7: ='Document Control'!C7 -> 3 - Significant Value | E7: Product Alignment | G7: ='Document Control'!G7 -> 4 - Full Product Alignment
B8: Story Type | C8: ='Document Control'!C8 -> Project | E8: Risk Rating | G8: ='Document Control'!G8 -> 1. Critical
B9: User Story Owner | C9: ='Document Control'!C9 -> 0 | E9: SMEs | G9: ='Document Control'!G9 -> 0
C10: ='Document Control'!C10 | E10: Work Bucket Type | G10: ='Document Control'!G10 -> FUN_Standard
C11: ='Document Control'!C11 | E11: Base Estimate (Points) | G11: ='Document Control'!G11 -> 8
B12: Business Process Flow Links | C12: ='Document Control'!C12 -> 0 | E12: Customer Estimate (Points) | G12: ='Document Control'!G12 -> 0
A14: Action Items Details
B15: S.No. | C15: Action Item - Description | D15: Resolution/Comments | E15: Assigned to | F15: Status | G15: Date Added | H15: Target Date | I15: Actual Completion Date | J15: Comments

Sheet Business Acceptance
B1: User Story Card - Business Acceptance
B2: Track acceptance criteria for this story, as well as child/dependent stories or project activities
B4: Product | C4: ='Document Control'!C4 -> PC | D4: Story Card # | F4: ='Document Control'!G4 -> US444
B5: Story Card Name | C5: ='Document Control'!C5 -> Policy Info | D5: Status | F5: ='Document Control'!G5 -> Not Started
B6: Theme | C6: ='Document Control'!C6 -> QuoteApplication | D6: GW-ID | F6: ='Document Control'!G6 -> 10900-GW.2
B7: ='Document Control'!B7 -> Gap Business Value | C7: ='Document Control'!C7 -> 3 - Significant Value | D7: Product Alignment | F7: ='Document Control'!G7 -> 4 - Full Product Alignment
B8: Story Type | C8: ='Document Control'!C8 -> Project | D8: Risk Rating | F8: ='Document Control'!G8 -> 1. Critical
B9: User Story Owner | C9: ='Document Control'!C9 -> 0 | D9: SMEs | F9: ='Document Control'!G9 -> 0
C10: ='Document Control'!C10 | D10: Work Bucket Type | F10: ='Document Control'!G10 -> FUN_Standard
C11: ='Document Control'!C11 | D11: Base Estimate (Points) | F11: ='Document Control'!G11 -> 8
B12: Business Process Flow Links | C12: ='Document Control'!C12 -> 0 | D12: Customer Estimate (Points) | F12: ='Document Control'!G12 -> 0
B14: SME or Product Owner Sign-Off of implemented functionality according to Acceptance Criteria
B17: Acceptance Details
B18: Requirement Number | C18: Acceptance Criteria | D18: User Story / Defect Number | E18: Success/Failure | F18: Wave or Release | G18: LOB
B37: Related Documentation
B38: Document Name/ID | C38: Document Description | F38: Document Link

Sheet UI Final
B1: User Story Card - UI Final
B2: Create screen shots of the final UI after all user story development has been completed
B4: Product | C4: ='Document Control'!C4 -> PC | E4: Story Card # | G4: ='Document Control'!G4 -> US444
B5: Story Card Name | C5: ='Document Control'!C5 -> Policy Info | E5: Status | G5: ='Document Control'!G5 -> Not Started
B6: Theme | C6: ='Document Control'!C6 -> QuoteApplication | E6: GW-ID | G6: ='Document Control'!G6 -> 10900-GW.2
B7: ='Document Control'!B7 -> Gap Business Value | C7: ='Document Control'!C7 -> 3 - Significant Value | E7: Product Alignment | G7: ='Document Control'!G7 -> 4 - Full Product Alignment
B8: Story Type | C8: ='Document Control'!C8 -> Project | E8: Risk Rating | G8: ='Document Control'!G8 -> 1. Critical
B9: User Story Owner | C9: ='Document Control'!C9 -> 0 | E9: SMEs | G9: ='Document Control'!G9 -> 0
C10: ='Document Control'!C10 | E10: Work Bucket Type | G10: ='Document Control'!G10 -> FUN_Standard
C11: ='Document Control'!C11 | E11: Base Estimate (Points) | G11: ='Document Control'!G11 -> 8
B12: Business Process Flow Links | C12: ='Document Control'!C12 -> 0 | E12: Customer Estimate (Points) | G12: ='Document Control'!G12 -> 0
B14: Enter name of the screen here

Sheet Implementation Details
B1: User Story Card - Implementation Details
B2: Record Implementation Details e.g. gosu classes, design notes, Object Model Changes, Integrations , references to external design documents
B4: Product | C4: ='Document Control'!C4 -> PC | E4: Story Card # | G4: ='Document Control'!G4 -> US444
B5: Story Card Name | C5: ='Document Control'!C5 -> Policy Info | E5: Status | G5: ='Document Control'!G5 -> Not Started
B6: Theme | C6: ='Document Control'!C6 -> QuoteApplication | E6: GW-ID | G6: ='Document Control'!G6 -> 10900-GW.2
B7: ='Document Control'!B7 -> Gap Business Value | C7: ='Document Control'!C7 -> 3 - Significant Value | E7: Product Alignment | G7: ='Document Control'!G7 -> 4 - Full Product Alignment
B8: Story Type | C8: ='Document Control'!C8 -> Project | E8: Risk Rating | G8: ='Document Control'!G8 -> 1. Critical
B9: User Story Owner | C9: ='Document Control'!C9 -> 0 | E9: SMEs | G9: ='Document Control'!G9 -> 0
C10: ='Document Control'!C10 | E10: Work Bucket Type | G10: ='Document Control'!G10 -> FUN_Standard
C11: ='Document Control'!C11 | E11: Base Estimate (Points) | G11: ='Document Control'!G11 -> 8
B12: Business Process Flow Links | C12: ='Document Control'!C12 -> 0 | E12: Customer Estimate (Points) | G12: ='Document Control'!G12 -> 0
B14: Enter Implementation Details here
B15: Requirement Number | C15: Implementation Notes

Sheet Estimation
B1: User Story Card - Estimation
B2: Track estimates here if you do not use Rally or the planner, or if you have other unique estimating requirements
B4: Product | C4: ='Document Control'!C4 -> PC | D4: Story Card # | E4: ='Document Control'!G4 -> US444
B5: Story Card Name | C5: ='Document Control'!C5 -> Policy Info | D5: Status | E5: ='Document Control'!G5 -> Not Started
B6: Theme | C6: ='Document Control'!C6 -> QuoteApplication | D6: GW-ID | E6: ='Document Control'!G6 -> 10900-GW.2
B7: ='Document Control'!B7 -> Gap Business Value | C7: ='Document Control'!C7 -> 3 - Significant Value | D7: Product Alignment | E7: ='Document Control'!G7 -> 4 - Full Product Alignment
B8: Story Type | C8: ='Document Control'!C8 -> Project | D8: Risk Rating | E8: ='Document Control'!G8 -> 1. Critical
B9: User Story Owner | C9: ='Document Control'!C9 -> 0 | D9: SMEs | E9: ='Document Control'!G9 -> 0
C10: ='Document Control'!C10 | D10: Work Bucket Type | E10: ='Document Control'!G10 -> FUN_Standard
C11: ='Document Control'!C11 | D11: Base Estimate (Points) | E11: ='Document Control'!G11 -> 8
B12: Business Process Flow Links | C12: ='Document Control'!C12 -> 0 | D12: Customer Estimate (Points) | E12: ='Document Control'!G12 -> 0
B14: Resource Type | C14: Hours | D14: % of Effort | E14: Comment
B15: BA | C15: 0 | D15: =IF(C15=0,0,(C15/tbl_Estimation[[#Totals],[Hours]])) -> 0
B16: DA | C16: 0 | D16: =IF(C16=0,0,(C16/tbl_Estimation[[#Totals],[Hours]])) -> 0
B17: Config. | C17: 0 | D17: =IF(C17=0,0,(C17/tbl_Estimation[[#Totals],[Hours]])) -> 0
B18: GW Int. | C18: 0 | D18: =IF(C18=0,0,(C18/tbl_Estimation[[#Totals],[Hours]])) -> 0
B19: Other Int. | C19: 0 | D19: =IF(C19=0,0,(C19/tbl_Estimation[[#Totals],[Hours]])) -> 0
B20: QA | C20: 0 | D20: =IF(C20=0,0,(C20/tbl_Estimation[[#Totals],[Hours]])) -> 0
B21: Infrast. | C21: 0 | D21: =IF(C21=0,0,(C21/tbl_Estimation[[#Totals],[Hours]])) -> 0
B22: Data Arch | C22: 0 | D22: =IF(C22=0,0,(C22/tbl_Estimation[[#Totals],[Hours]])) -> 0
B23: ETL | C23: 0 | D23: =IF(C23=0,0,(C23/tbl_Estimation[[#Totals],[Hours]])) -> 0
B24: BI | C24: 0 | D24: =IF(C24=0,0,(C24/tbl_Estimation[[#Totals],[Hours]])) -> 0
B25: DP Config | C25: 0 | D25: =IF(C25=0,0,(C25/tbl_Estimation[[#Totals],[Hours]])) -> 0
B26: DP Look And Feel | C26: 0 | D26: =IF(C26=0,0,(C26/tbl_Estimation[[#Totals],[Hours]])) -> 0
B27: Totals | C27: =SUBTOTAL(109,tbl_Estimation[Hours]) -> 0 | D27: =SUBTOTAL(109,tbl_Estimation[% of Effort]) -> 0
B29: Estimate Assumptions

Sheet Dropdown Lists
A1: Products | C1: UserStory Status | E1: Story Type | G1: Action Items Status | I1: Product Alignment Values | K1: Business Value | M1: Theme | O1: Boolean | Q1: Story Risk
A2: PolicyCenter | C2: Not Started | E2: OOTB | G2: New | I2: 4 - Full Product Alignment | K2: 4 - Highest Value | M2: 8.0 Upgrade, Optional | O2: TRUE | Q2: 1. Critical
A3: BillingCenter | C3: In Progress | E3: Modified | G3: In Progress | I3: 3 - Significant Alignment | K3: 3 - Significant Value | M3: 8.0 Upgrade, Required | O3: FALSE | Q3: 2. High
A4: ClaimCenter | C4: In Review | E4: New | G4: Completed | I4: 2 - Moderate Alignment | K4: 2 - Moderate Value | M4: Accelerators | Q4: 3. Medium
A5: Rating | C5: Approved | G5: Delayed | I5: 1 - Minimal Alignment | K5: 1 - Minimal Value | M5: Account | Q5: 4. Low
A6: Reinsurance | C6: Final | I6: 0 - No Alignment | K6: 0 - No Value | M6: Account Synchronization
A7: Mobile & Portal | M7: Address Verification
A8: DataHub | M8: Adjudicate
A9: InfoCenter | M9: Admin
M10: Agency Management System
M11: Authentication
M12: Auto Estimate
M13: Auto Salvage
M14: Automated Document Production
M15: Base Product Installation
M16: BC to CC - Aggregate Limit determination
M17: Billing / Payment Plans
M18: Billing Inquiry
M19: Billing Instructions
M20: Billing System Cancellation Requests
M21: Bind/Issue
... M265: Workers Comp Reporting
